starting up user application
forwarding local port 5000 to external port 80 (mapped as 1104)

(Background on this error at: https://sqlalche.me/e/20/e3q8)
                             ^^^^^^^^^^^^^^^^^^^^^^^
           ^^^^^^^^^^^^^^^^^^^^^^^^^^^^^^^^
  File "/home/runner/workspace/.pythonlibs/lib/python3.11/site-packages/sqlalchemy/engine/base.py", line 143, in __init__
    with util.safe_reraise():
    conn = _connect(dsn, connection_factory=connection_factory, **kwasync)
  File "/home/runner/workspace/.pythonlibs/lib/python3.11/site-packages/sqlalchemy/engine/base.py", line 3301, in raw_connection
  File "/home/runner/workspace/.pythonlibs/lib/python3.11/site-packages/sqlalchemy/engine/create.py", line 661, in connect
    self._dbapi_connection = engine.raw_connection()

Traceback (most recent call last):
(Background on this error at: https://sqlalche.me/e/20/e3q8)
    with util.safe_reraise():
         ^^^^^^^^^^^^^^
(Background on this error at: https://sqlalche.me/e/20/e3q8)
                             ^^^^^^^^^^^^^^^^^^^^^^^
    conn = _connect(dsn, connection_factory=connection_factory, **kwasync)

(Background on this error at: https://sqlalche.me/e/20/e3q8)
  File "/home/runner/workspace/.pythonlibs/lib/python3.11/site-packages/sqlalchemy/pool/base.py", line 447, in connect
    raise exc_value.with_traceback(exc_tb)
            ^^^^^^^^^^^^^^^^^^^^^^^^^^^^^^^^
  File "/home/runner/workspace/.pythonlibs/lib/python3.11/site-packages/sqlalchemy/pool/base.py", line 1264, in _checkout
(Background on this error at: https://sqlalche.me/e/20/e3q8)
  File "/home/runner/workspace/.pythonlibs/lib/python3.11/site-packages/sqlalchemy/pool/base.py", line 895, in __connect
           ^^^^^^^^^^^^^^^^^^^^^^^^^^^^^^^^
(Background on this error at: https://sqlalche.me/e/20/e3q8)
    return _ConnectionFairy._checkout(self)
  File "/home/runner/workspace/.pythonlibs/lib/python3.11/site-packages/sqlalchemy/engine/base.py", line 143, in __init__
           ^^^^^^^^^^^^^^^^^^^^^^^
  File "/home/runner/workspace/.pythonlibs/lib/python3.11/site-packages/psycopg2/__init__.py", line 122, in connect
  File "/home/runner/workspace/.pythonlibs/lib/python3.11/site-packages/sqlalchemy/engine/base.py", line 2440, in _handle_dbapi_exception_noconnection
command finished with error [sh -c python main.py]: exit status 1
2025-08-29 12:43:06,164 - root - ERROR - Database initialization error: (psycopg2.OperationalError) connection to server at "traitortrack.cfi40ye0yasz.ap-south-1.rds.amazonaws.com" (13.204.126.204), port 5432 failed: timeout expired
(Background on this error at: https://sqlalche.me/e/20/e3q8)
           ^^^^^^^^^^^^^^^^^^^^^^^^^^^^^^^^
    return _ConnectionRecord(self)
  File "/home/runner/workspace/.pythonlibs/lib/python3.11/site-packages/sqlalchemy/engine/create.py", line 661, in connect
           ^^^^^^^^^^^^^^^^^^^
    with util.safe_reraise():
    raise exc_value.with_traceback(exc_tb)
           ^^^^^^^^^^^^^^^^^^^^^^^^^^^^^^^^
    db.create_all()
           ^^^^^^^^^^^^^^^^^^^
    return _ConnectionFairy._checkout(self)
  File "/home/runner/workspace/.pythonlibs/lib/python3.11/site-packages/sqlalchemy/pool/base.py", line 895, in __connect
           ^^^^^^^^^^^^^^^^^^^^^^^
a port configuration was specified but the required port was never opened
2025-08-29T12:43:57Z error: The deployment failed because the application failed to open a port in time. This can happen because the application takes to long to open a server, or doesn't open one at all on the expected port. Note that this doesn't mean that the application is crashing, only that it's not opening a port in time. The application must serve traffic on the first port specified as 'localPort' in the port configuration specified in the .replit file. Make sure that the application opens a port quickly and that there are no operations taking too long on startup. Check the logs for more information.
